Workbook

Sheet Convenzioni codifica
A1: Prefisso codifica | B1: Significato
A2: INF# | B2: Input estratti da Zucchetti Infinity (Co.Ge.).
A3: E / R / RA / C / CS / I | B3: Codici voce del Conto Economico gestionale.
A4: C20 | B4: Input estratti da Campus 2.0 (Tool Incentive).
A5: TG# | B5: Tabelle guida CDG.
A6: P# | B6: Processi (Actual / Forecast).
A7: O1# | B7: Output del modulo.
A8: RIB# | B8: Regole di ribaltamento
A9: STEP# | B9: Step delle regole di proiezione Forecast

Sheet Dizionario campi
A1: Codice campo | B1: Campo | C1: Fonte
A2: D0 | B2: Data estrazione | C2: Campus / Infinity
A3: D1 | B3: Data erogazione | C3: Campus
A4: D2 | B4: Anno di riferimento | C4: Campus / Infinity
A5: D3 | B5: Mese di riferimento | C5: Campus / Infinity
A6: D4 | B6: Categoria prodotto | C6: Campus / Infinity
A7: D5 | B7: Tipo tasso | C7: Campus
A8: D6 | B8: Istituto | C8: Campus
A9: D7 | B9: Collaboratore | C9: Campus
A10: D8 | B10: Gestore | C10: Campus
A11: D9 | B11: Tutor | C11: Campus
A12: D10 | B12: Senior | C12: Campus
... A45: D44 | B45: Codice fiscale gestore | C45: Campus

Sheet TG1-Anagrafica Prodotti
A1: Codice campo | B1: Campo | C1: Fonte | D1: Valori possibili
A2: =+INDEX('Dizionario campi'!A:A,MATCH(B2,'Dizionario campi'!B:B,0),1) -> D17 | B2: Tipo Mediazione | C2: Campus 2.0 | D2: Creditizia / Assicurativa
A3: =+INDEX('Dizionario campi'!A:A,MATCH(B3,'Dizionario campi'!B:B,0),1) -> D4 | B3: Categoria prodotto | C3: Campus 2.0 | D3: Mutuo, Prestito personale, Prestito corporate, CQS, Polizza, Consulenza)
A4: =+INDEX('Dizionario campi'!A:A,MATCH(B4,'Dizionario campi'!B:B,0),1) -> D20 | B4: ID Prodotto | C4: Campus 2.0
A5: =+INDEX('Dizionario campi'!A:A,MATCH(B5,'Dizionario campi'!B:B,0),1) -> D21 | B5: Prodotto | C5: Campus 2.0
A6: =+INDEX('Dizionario campi'!A:A,MATCH(B6,'Dizionario campi'!B:B,0),1) -> D22 | B6: Tipologia tasso | C6: Campus 2.0 | D6: Fisso, Misto, Variabile, Cap, Altri prodotti

Sheet TG2-Anarafica Istituti
A1: Codice campo | B1: Campo | C1: Fonte
A2: =+INDEX('Dizionario campi'!A:A,MATCH(B2,'Dizionario campi'!B:B,0),1) -> D23 | B2: ID Istituto | C2: Campus
A3: =+INDEX('Dizionario campi'!A:A,MATCH(B3,'Dizionario campi'!B:B,0),1) -> D6 | B3: Istituto | C3: Campus
A4: =+INDEX('Dizionario campi'!A:A,MATCH(B4,'Dizionario campi'!B:B,0),1) -> D24 | B4: Città istituto | C4: Campus

Sheet TG3-Anagrafica Reti-Agenti
A1: Codice campo | B1: Campo | C1: Fonte | H1: Gerarchia: | I1: 1. Responsabile area
A2: =+INDEX('Dizionario campi'!A:A,MATCH(B2,'Dizionario campi'!B:B,0),1) -> D11 | B2: Responsabile area | C2: Campus | I2: 2. Agenzia
A3: =+INDEX('Dizionario campi'!A:A,MATCH(B3,'Dizionario campi'!B:B,0),1) -> D36 | B3: Codice fiscale responsabile area | C3: Campus | I3: 3. Senior manager
A4: =+INDEX('Dizionario campi'!A:A,MATCH(B4,'Dizionario campi'!B:B,0),1) -> D37 | B4: ID Agenzia | C4: Campus | I4: 4. Tutor
A5: =+INDEX('Dizionario campi'!A:A,MATCH(B5,'Dizionario campi'!B:B,0),1) -> D12 | B5: Agenzia Kiron | C5: Campus | I5: 5. Gestore
A6: =+INDEX('Dizionario campi'!A:A,MATCH(B6,'Dizionario campi'!B:B,0),1) -> D41 | B6: Codice fiscale senior manager | C6: Campus | I6: 6. Collaboratore
A7: =+INDEX('Dizionario campi'!A:A,MATCH(B7,'Dizionario campi'!B:B,0),1) -> D42 | B7: Senior manager | C7: Campus
A8: =+INDEX('Dizionario campi'!A:A,MATCH(B8,'Dizionario campi'!B:B,0),1) -> D43 | B8: Codice fiscale tutor | C8: Campus
A9: =+INDEX('Dizionario campi'!A:A,MATCH(B9,'Dizionario campi'!B:B,0),1) -> D9 | B9: Tutor | C9: Campus
A10: =+INDEX('Dizionario campi'!A:A,MATCH(B10,'Dizionario campi'!B:B,0),1) -> D44 | B10: Codice fiscale gestore | C10: Campus
A11: =+INDEX('Dizionario campi'!A:A,MATCH(B11,'Dizionario campi'!B:B,0),1) -> D8 | B11: Gestore | C11: Campus
A12: =+INDEX('Dizionario campi'!A:A,MATCH(B12,'Dizionario campi'!B:B,0),1) -> D38 | B12: Codice fiscale collaboratore | C12: Campus
A13: =+INDEX('Dizionario campi'!A:A,MATCH(B13,'Dizionario campi'!B:B,0),1) -> D7 | B13: Collaboratore | C13: Campus
A14: =+INDEX('Dizionario campi'!A:A,MATCH(B14,'Dizionario campi'!B:B,0),1) -> D39 | B14: Data inizio | C14: Campus
A15: =+INDEX('Dizionario campi'!A:A,MATCH(B15,'Dizionario campi'!B:B,0),1) -> D40 | B15: Data fine | C15: Campus

Sheet TG4-Mappatura bilancio
A1: Conto contabile | B1: Voce | C1: Codice raggr. voce gestionale | D1: Codice voce gestionale | E1: Riclassificazione gestionale | F1: Tipo dato | G1: Voce bilancio gestionale | H1: Periodicità riconciliazione
A2: T5001010 | B2: Cancelleria | C2: CS3 | D2: CS3.5 | E2: Costi di struttura 3 | F2: Costi struttura | G2: Cancelleria | H2: Mensile
A3: T5001020 | B3: Materiale di consumo | C3: CS3 | D3: CS3.6 | E3: Costi di struttura 3 | F3: Costi struttura | G3: Materiale di consumo | H3: Mensile
A4: T5001030 | B4: Modulistica e stampati | C4: CS3 | D4: CS3.7 | E4: Costi di struttura 3 | F4: Costi struttura | G4: Modulistica e stampati | H4: Mensile
A5: T5001040 | B5: Materiali e accessori | C5: CS3 | D5: CS3.8 | E5: Costi di struttura 3 | F5: Costi struttura | G5: Materiali e accessori | H5: Mensile
A6: T5101001 | B6: Compenso amministratori e sindaci | C6: CS2 | D6: CS2.1 | E6: Costi di struttura 2 | F6: Costi struttura | G6: Compenso amministratori e sindaci | H6: Mensile
A7: T5101002 | B7: Contributi Co.Co.Co. | C7: CS2 | D7: CS2.2 | E7: Costi di struttura 2 | F7: Costi struttura | G7: Contributi Co.Co.Co. | H7: Mensile
A8: T5101003 | B8: Contributi Co.Co.Co. | C8: CS2 | D8: CS2.2 | E8: Costi di struttura 2 | F8: Costi struttura | G8: Contributi Co.Co.Co. | H8: Mensile
A9: T5101005 | B9: Compenso amministratori e sindaci | C9: CS2 | D9: CS2.1 | E9: Costi di struttura 2 | F9: Costi struttura | G9: Compenso amministratori e sindaci | H9: Mensile
A10: T5101006 | B10: Consulenze tecniche | C10: CS2 | D10: CS2.3 | E10: Costi di struttura 2 | F10: Costi struttura | G10: Consulenze tecniche | H10: Mensile
A11: T5101007 | B11: Consulenze legali | C11: CS2 | D11: CS2.4 | E11: Costi di struttura 2 | F11: Costi struttura | G11: Consulenze legali | H11: Mensile
A12: T5101008 | B12: Consulenze fiscali, amministrative ed elaborazione paghe | C12: CS2 | D12: CS2.5 | E12: Costi di struttura 2 | F12: Costi struttura | G12: Consulenze fiscali, amministrative ed elaborazione paghe | H12: Mensile
... A154: T8015002 | B154: Provvigioni attive | C154: R1 | D154: R1.1 | E154: Payin clienti | F154: Ricavi | G154: Provvigioni attive da clienti | H154: Mensile

Sheet TG5-Elenco voci con standard
A1: Codice raggr. voce gestionale | B1: Codice voce gestionale | C1: Riclassificazione gestionale | D1: Tipo dato | E1: Codice regole stima std | F1: Parametro stima std | G1: Valore parametro | H1: Importo stimato | I1: Periodo
A2: CS3 | B2: CS3.5 | C2: Costi di struttura 3 | D2: Costi struttura | E2: STD# | F2: tbd
A3: CS3 | B3: CS3.6 | C3: Costi di struttura 3 | D3: Costi struttura | E3: STD# | F3: tbd
A4: CS3 | B4: CS3.7 | C4: Costi di struttura 3 | D4: Costi struttura | E4: STD# | F4: tbd
A5: CS3 | B5: CS3.8 | C5: Costi di struttura 3 | D5: Costi struttura | E5: STD# | F5: tbd
A6: CS2 | B6: CS2.1 | C6: Costi di struttura 2 | D6: Costi struttura | E6: STD1 | F6: *% risorse - o del costo del personale - che si dedicano a ciascuna famiglia di prodotti
A7: CS2 | B7: CS2.2 | C7: Costi di struttura 2 | D7: Costi struttura | E7: STD1 | F7: *% risorse - o del costo del personale - che si dedicano a ciascuna famiglia di prodotti
A8: CS2 | B8: CS2.3 | C8: Costi di struttura 2 | D8: Costi struttura | E8: STD1 | F8: *% risorse - o del costo del personale - che si dedicano a ciascuna famiglia di prodotti
A9: CS2 | B9: CS2.4 | C9: Costi di struttura 2 | D9: Costi struttura | E9: STD1 | F9: *% risorse - o del costo del personale - che si dedicano a ciascuna famiglia di prodotti
A10: CS2 | B10: CS2.5 | C10: Costi di struttura 2 | D10: Costi struttura | E10: STD1 | F10: *% risorse - o del costo del personale - che si dedicano a ciascuna famiglia di prodotti
A11: CS2 | B11: CS2.6 | C11: Costi di struttura 2 | D11: Costi struttura | E11: STD1 | F11: *% risorse - o del costo del personale - che si dedicano a ciascuna famiglia di prodotti
A12: CS2 | B12: CS2.7 | C12: Costi di struttura 2 | D12: Costi struttura | E12: STD1 | F12: *% risorse - o del costo del personale - che si dedicano a ciascuna famiglia di prodotti
A13: CS1 | B13: CS1.1 | C13: Costi di struttura 1 | D13: Costi struttura | E13: STD# | F13: tbd
... A80: R3 | B80: R3.1 | C80: Rappel | D80: Ricavi | E80: STD8 | F80: rappel quantitativi (varia per istituto e per scaglioni produttivi dimensionali (crescita scaglioni marginali)) + (collocamento assicurativo su prodotto mutui) + rappel qualitativi (tbd,tbd7% sulle pratiche con più di tre rate arretrate)

Sheet TG5.1-Regole standard
A1: STD1 | B1: Griglia con categoria prodotti e incidenza dei costi risorse | K1: STD1 | L1: *% risorse - o del costo del personale - che si dedicano a ciascuna famiglia di prodotti
A2: Misure | B2: Costi di struttura 2 (CS2) | K2: STD2 | L2: da ribaltare in modo omogeneo sui senior aderenti (quindi i senior avranno costi propri + costi imputati) - OPEN POINT
A3: Data di riferimento | B3: Categoria prodotto | C3: base di allocazione | D3: Incidenza costi risorse | E3: Importo stimato | F3: Conferma | K3: STD3 | L3: n. collaboratori * % max enasarco * % di collaboratori che raggiungono il cap
K4: STD4 | L4: 1% dei ricavi solo per mediazione creditizia. Da calcolare sulle provvigioni passive
K5: STD5 | L5: % da stimare sul fatturato della propria area per ciascun responsabile area
K6: STD6 | L6: da ribaltare in modo omogeneo su tutti i prodotti / pratiche delle filiere aderenti
A7: STD2 | B7: da ribaltare in modo omogeneo sui senior aderenti (quindi i senior avranno costi propri + costi imputati) - OPEN POINT | K7: STD7 | L7: Collaboratore (incentivo a scaglioni dimensionali suddiviso per senior manager 2/3 e collaboratore 1/3 ); sotto incentivazione della filiera a scaglioni dimensionali; sotto incentivazione di specifici prodotti (cqs, prestiti personali). Imputabile al prodotto in modo % rispetto ai ricavi
A8: Misure | B8: Payout progetto giovani (C9) | K8: STD8 | L8: rappel quantitativi (varia per istituto e per scaglioni produttivi dimensionali (crescita scaglioni marginali)) + (collocamento assicurativo su prodotto mutui) + rappel qualitativi (tbd,tbd7% sulle pratiche con più di tre rate arretrate)
A9: Data di riferimento | B9: Senior | C9: base di allocazione | D9: Criterio % | E9: Importo stimato | F9: Conferma | K9: STD9 | L9: 28% dell'Ebit
K10: STD# | L10: tbd
A12: STD3 | B12: Griglia con numero collaboratori, quota dei collaboratori che si ipotizza raggiungano il cap e il cap aliquota Enasarco
A13: Misure | B13: Enasarco (C1)
A14: Data di riferimento | B14: N. collaboratori | C14: Quota % collaboratori che si ipotizza raggiungano il cap | D14: Cap aliquota Enasarco | E14: Importo stimato | F14: Conferma
C15: compilazione manuale
A17: STD4 | B17: Griglia con payout mediazione creditizia e criterio %
A18: Misure | B18: FIRR (C2)
A19: Data di riferimento | B19: Tipo Mediazione | C19: Payout | D19: Criterio % | E19: Importo stimato | F19: Conferma
B20: Creditizia | D20: 0.01
A23: STD5 | B23: Griglia con fatturato per responsabile d'area e criterio %
A24: Misure | B24: Consulenza d'area (C6)
A25: Data di riferimento | B25: Responsabile area | C25: Fatturato | D25: Criterio % | E25: Importo stimato | F25: Conferma
A28: STD6 | B28: da ribaltare in modo omogeneo su tutti i prodotti / pratiche delle filiere aderenti
A29: Misure | B29: Ricavi compartecipazione progetto giovani (R4)
A30: Data di riferimento | B30: Prodotto / Pratica | C30: Agenzia Kiron | D30: base di allocazione | E30: Criterio % | F30: Importo stimato | G30: Conferma
C31: Solo aderenti progetti giovani
A34: STD7 | B34: Collaboratore (incentivo a scaglioni dimensionali suddiviso per senior manager 2/3 e collaboratore 1/3 ); sotto incentivazione della filiera a scaglioni dimensionali; sotto incentivazione di specifici prodotti (cqs, prestiti personali). Imputabile al prodotto in modo % rispetto ai ricavi
A35: Misure | B35: Incentivi (C3)
A36: Data di riferimento | B36: Scaglione dimensionale | C36: Ruolo agente | D36: base di allocazione | E36: Criterio % | F36: Importo stimato | G36: Conferma
C37: Solo Collaboratore e Senior
A40: Data di riferimento | B40: Scaglione dimensionale | C40: Agenzia Kiron | D40: base di allocazione | E40: Criterio % | F40: Importo stimato | G40: Conferma
A43: Data di riferimento | B43: Categoria prodotto | C43: Payin | D43: Criterio % | E43: Importo stimato | F43: Conferma
B44: Solo CQS e Presiti personali
A47: STD8 | B47: rappel quantitativi (varia per istituto e per scaglioni produttivi dimensionali (crescita scaglioni marginali)) + (collocamento assicurativo su prodotto mutui) + rappel qualitativi (tbd,tbd7% sulle pratiche con più di tre rate arretrate)
A48: Misure | B48: Rappel (R3)
A49: Data di riferimento | B49: Scaglione dimensionale | C49: Istituto | D49: base di allocazione | E49: Criterio %
A51: Data di riferimento | B51: tbd | C51: Tipo pratica | D51: base di allocazione | E51: Criterio %
A54: STD9 | B54: Griglia con Ebit e criterio %
A55: Data di riferimento | B55: Ebit* | C55: Criterio % | D55: Importo stimato | E55: Conferma
A56: *Ebit = utile d'esercizio al netto di minusvalenze, rettifiche finanziarie e imposte
A59: STD# | B59: Altro tbd
...

Sheet TG6-Dati propedeutici forecast
A1: Codice campo | B1: Campo | C1: Fonte
A2: =+INDEX('Dizionario campi'!A:A,MATCH(B2,'Dizionario campi'!B:B,0),1) -> D19 | B2: Data di riferimento | C2: Campus
A3: =+INDEX('Dizionario campi'!A:A,MATCH(B3,'Dizionario campi'!B:B,0),1) -> D33 | B3: Misura per calcolo proiezioni | C3: (erogato, share istituto, redditività istituto)
A4: =+INDEX('Dizionario campi'!A:A,MATCH(B4,'Dizionario campi'!B:B,0),1) -> D34 | B4: Crescita % YoY | C4: Campus
A5: =+INDEX('Dizionario campi'!A:A,MATCH(B5,'Dizionario campi'!B:B,0),1) -> D4 | B5: Categoria prodotto | C5: Campus
A6: =+INDEX('Dizionario campi'!A:A,MATCH(B6,'Dizionario campi'!B:B,0),1) -> D17 | B6: Tipo Mediazione | C6: Campus
A7: =+INDEX('Dizionario campi'!A:A,MATCH(B7,'Dizionario campi'!B:B,0),1) -> D6 | B7: Istituto | C7: Campus

Sheet RIB-Elenco voci con regole rib
A1: Codice voce | B1: Voce | C1: Descrizione | D1: Fonte | E1: Regola di ribaltamento | F1: Cod. regola
A2: E1 | B2: Erogato | C2: Erogato | D2: Campus | E2: - | F2: -
A3: R1 | B3: Provvigioni attive da clienti | C3: Payin da clienti | D3: Campus | E3: — | F3: -
A4: R2 | B4: Provvigioni attive da istituti | C4: Payin da istituti | D4: Campus | E4: — | F4: -
A5: R3 | B5: Rappel | C5: Commissione attiva aggiuntiva | D5: Infinity | E5: Payin mediazione creditizia | F5: RIB1
A6: R4 | B6: Ricavi compartecipazione progetto giovani | C6: Ricavi da progetto giovani | D6: Infinity | E6: Payin agenzie progetto giovani | F6: RIB2
A7: RA1 | B7: Altri ricavi | C7: Concessione marchio, contributi, plusvalenze, sopravvenienze, ecc. | D7: Infinity | E7: In base al totale payin | F7: RIB3
A8: C1 | B8: Enasarco | C8: Contributi previdenziali agenti | D8: Infinity | E8: Payout med. creditizia | F8: RIB4
A9: C2 | B9: FIRR | C9: Indennità di fine rapporto agenti | D9: Infinity | E9: Payout med. creditizia | F9: RIB4
A10: C3 | B10: Incentivi | C10: Incentivi passivi | D10: Campus 2.0 | E10: In base al totale payin | F10: RIB3
A11: C4 | B11: Provvigioni passive (Payout) | C11: Commissioni passive v/agenti | D11: Campus | E11: — | F11: -
A12: C5 | B12: Servizi certificazione documentale | C12: Costi Due diligence da Genio | D12: Infinity | E12: Erogato mutuo | F12: RIB5
... A18: I1 | B18: Imposte | C18: — | D18: Stima | E18: 28% EBIT | F18: -

Sheet RIB.1-Regole ribaltamento
A1: RIB1 | B1: Ribaltamento del rappel in base al payin della mediazione creditizia sulle dimensioni di analisi prodotto - istituto - rete
A2: Misure | B2: Rappel (R3)
A3: Data di riferimento | B3: Prodotto | C3: Tipo tasso | D3: Istituto | E3: Collaboratore | F3: Payin | G3: Totale payin mediazione creditizia | H3: Incidenza Payin su Totale payin mediazione creditizia | I3: Rappel totale di periodo | J3: Rappel ribaltato
H4: Criterio % | I4: Base allocazione | J4: Output
A6: RIB2 | B6: Ribaltamento del payin progetto giovani, del payout progetto giovani e dei rimborsi in base al al payin delle agenzie aderenti al progetto giovani sulle dimensioni di analisi prodotto - istituto - rete
A7: Misure | B7: Ricavi compartecipazione progetto giovani (R4), Rimborsi agenti (C8), Payout progetto giovani (C9)
A8: Data di riferimento | B8: Prodotto | C8: Tipo tasso | D8: Istituto | E8: Collaboratore | F8: Payin | G8: Totale payin agenzie aderenti progetto giovani | H8: Incidenza Payin su Totale payin agenzie aderenti progetto giovani | I8: Payin progetto giovani totale di periodo | J8: Payin progetto giovani ribaltato | K8: Payout progetto giovani totale di periodo | L8: Payout progetto giovani ribaltato | M8: Rimborsi totale di periodo | N8: Rimborsi ribaltato
E9: Solo agenzie progetto giovani | H9: Criterio % | I9: Base allocazione | J9: Output | K9: Base allocazione | L9: Output | M9: Base allocazione | N9: Output
A11: RIB3 | B11: Ribaltamento degli altri ricavi e degli incentivi passivi in base al payin sulle dimensioni di analisi prodotto - istituto - rete
A12: Misure | B12: Altri ricavi (RA1), Incentivi passivi (C3)
A13: Data di riferimento | B13: Prodotto | C13: Tipo tasso | D13: Istituto | E13: Collaboratore | F13: Payin | G13: Totale payin | H13: Incidenza Payin su Totale payin | I13: Altri ricavi totali di periodo | J13: Altri ricavi ribaltati | K13: Incentivi passivi totali di periodo | L13: Incentivi passivi ribaltati
H14: Criterio % | I14: Base allocazione | J14: Output | K14: Base allocazione | L14: Output
A16: RIB4 | B16: Ribaltamento dell'Enasarco e del FIRR in base al payout della mediazione creditizia sulle dimensioni di analisi prodotto - istituto - rete
A17: Misure | B17: Enasarco (C1), FIRR (C2)
A18: Data di riferimento | B18: Prodotto | C18: Tipo tasso | D18: Istituto | E18: Collaboratore | F18: Payout | G18: Totale payout mediazione creditizia | H18: Incidenza Payout su Totale payout mediazione creditizia | I18: Enasarco totale di periodo | J18: Enasarco ribaltato | K18: FIRR totale di periodo | L18: FIRR ribaltato
B19: Solo mediazione creditizia | H19: Criterio % | I19: Base allocazione | J19: Output | K19: Base allocazione | L19: Output
A22: RIB5 | B22: Ribaltamento dei servizi di certificazione documentale in base all'erogato mutuo sulle dimensioni di analisi prodotto - istituto - rete
A23: Misure | B23: Servizi certificazione documentale (C5)
A24: Data di riferimento | B24: Prodotto | C24: Tipo tasso | D24: Istituto | E24: Collaboratore | F24: Erogato | G24: Totale erogato mutuo | H24: Incidenza Erogato mutuo su Totale erogato mutuo | I24: Servizi certificazione documentale totale di periodo | J24: Servizi certificazione documentale ribaltato
B25: Solo mutuo | H25: Criterio % | I25: Base allocazione | J25: Output
A28: RIB6 | B28: Ribaltamento della consulenza d'area in base al payin dell'area sulle dimensioni di analisi prodotto - istituto - rete
A29: Misure | B29: Consulenza d'area e incentivi consulenza credito (C6)
A30: Data di riferimento | B30: Prodotto | C30: Tipo tasso | D30: Istituto | E30: Collaboratore | F30: Payin | G30: Totale Payin area | H30: Incidenza Payin su Totale Payin area | I30: Consulenza d'area e incentivi consulenza del credito totale di periodo | J30: Consulenza d'area e incentivi consulenza del credito ribaltato
H31: Criterio % | I31: Base allocazione | J31: Output
A34: RIB# | B34: Ribaltamento dei costi di struttura in base a … sulle dimensioni di analisi prodotto - istituto - rete
A35: Misure | B35: Costi di struttura 1-10 (CS1-CS10)
A36: Data di riferimento | B36: Prodotto | C36: Tipo tasso | D36: Istituto | E36: Collaboratore | F36: tbd | G36: Totale tbd | H36: Incidenza tbd su Totale tbd | I36: Costi di struttura 1 totali di periodo | J36: Costi di struttura 1 ribaltati | K36: Costi di struttura 2 totali di periodo | L36: Costi di struttura 2 ribaltati | M36: Costi di struttura 3 totali di periodo | N36: Costi di struttura 3 ribaltati | O36: Costi di struttura 4 totali di periodo | P36: Costi di struttura 4 ribaltati | Q36: Costi di struttura 5 totali di periodo | R36: Costi di struttura 5 ribaltati | S36: Costi di struttura 6 totali di periodo | T36: Costi di struttura 6 ribaltati | U36: Costi di struttura 7 totali di periodo | V36: Costi di struttura 7 ribaltati | W36: Costi di struttura 8 totali di periodo | X36: Costi di struttura 8 ribaltati | Y36: Costi di struttura 9 totali di periodo | Z36: Costi di struttura 9 ribaltati | AA36: Costi di struttura 10 totali di periodo | AB36: Costi di struttura 10 ribaltati
H37: Criterio % | I37: Base allocazione | J37: Output | K37: Base allocazione | L37: Output | M37: Base allocazione | N37: Output | O37: Base allocazione | P37: Output | Q37: Base allocazione | R37: Output | S37: Base allocazione | T37: Output | U37: Base allocazione | V37: Output | W37: Base allocazione | X37: Output | Y37: Base allocazione | Z37: Output | AA37: Base allocazione | AB37: Output

Sheet STEP-Elenco voci regole proiez
A1: Step | B1: Aggregazione | C1: Voce | D1: Variabili base calcolo | E1: Parametri | F1: Logica proiezione
A2: 0 | B2: Erogato | C2: Erogato | D2: Erogato anno N-1 per ciascun prodotto e istituto | E2: % crescita per singolo prodotto | F2: Applicazione della % di crescita definita al valore actual dell'esercizio precedente.
A3: 1 | B3: Ricavi | C3: Payin clienti (solo Mutuo) | D3: Erogato per prodotto Mutuo (per istituto, per anno) | E3: % crescita erogato Mutuo; incidenza % payin cliente / erogato; per i primi “N” istituti: share e redditività cliente per istituto | F3: Redditività cliente applicata all'erogato previsto; raffinabile per istituto sui primi “N”.
A4: 2 | B4: Ricavi | C4: Payin istituti (tutti i prodotti) | D4: Erogato per prodotto (per istituto, per anno) | E4: % crescita erogato per prodotto; incidenza % payin istituto / erogato; per Mutuo e Prestiti: share e redditività istituto per i primi 8 | F4: Redditività istituto applicata all'erogato previsto; raffinabile per istituto su Mutuo e Prestiti.
A5: 3 | B5: Ricavi | C5: Rappel (mediaz. creditizia) | D5: Valore actual N-1 per prodotto | E5: % crescita per singolo prodotto | F5: Applicazione della % di crescita definita al valore actual dell'esercizio precedente.
A6: 4 | B6: Ricavi | C6: Ricavi progetto giovani | D6: Valore actual N-1 per prodotto | E6: % crescita per singolo prodotto | F6: Applicazione della % di crescita definita al valore actual dell'esercizio precedente.
A7: 5 | B7: Altri Ricavi | C7: Altri ricavi (concessione marchio, plusvalenze, rimborsi, ecc.) | D7: Payin totale per prodotto (da step 1–2) | E7: Nessun parametro autonomo | F7: Seguono la crescita % del payin totale per prodotto — aggiornamento in cascata dagli step 1–2.
A8: 6 | B8: Costi Diretti | C8: Payout (tutti i prodotti) | D8: Payin totale per prodotto / istituto (da step 1–2) | E8: Nessun parametro autonomo | F8: Cresce delle stesse percentuali del payin totale per prodotto / istituto — cascata da step 1–2.
A9: 7 | B9: Costi Diretti | C9: Servizi di certificazione documentale (solo Mutuo) | D9: Erogato Mutuo (da step 1) | E9: Nessun parametro autonomo | F9: Segue la crescita % dell'erogato Mutuo — cascata da step 1.
A10: 8 | B10: Costi Diretti | C10: Enasarco (mediaz. creditizia) | D10: Payin totale mediaz. creditizia (da step 1–2, escluso Assicurazione) | E10: Nessun parametro autonomo | F10: Cresce proporzionalmente al payin di mediazione creditizia — cascata da step 1–2.
A11: 9 | B11: Costi Diretti | C11: FIRR (mediaz. creditizia) | D11: Payin totale mediaz. creditizia (da step 1–2, escluso Assicurazione) | E11: Aliquota fissa 1% (convenzionale, aggiornabile) | F11: Pari all'1% del payin di mediazione creditizia dell'anno in corso.
A12: 10 | B12: Costi Diretti | C12: Incentivi passivi | D12: Valore actual N-1 per prodotto | E12: % crescita per singolo prodotto | F12: Applicazione della % di crescita definita al valore actual dell'esercizio precedente.
A13: 11 | B13: Costi Diretti | C13: Consulenza d'area | D13: Valore actual N-1 per prodotto | E13: % crescita per singolo prodotto | F13: Applicazione della % di crescita definita al valore actual dell'esercizio precedente.
... A17: 15 | B17: Imposte | C17: Imposte sul reddito | D17: EBIT dell'anno in corso (risultante dal CE dopo tutte le voci precedenti, al netto di minusvalenze e rettifiche) | E17: Aliquota convenzionale 28% (aggiornabile su indicazione Direzione Kiron) | F17: Pari al 28% dell'EBIT dell'anno in corso.
